Workbook

Sheet PAUTA 1
A1: Pauta de Evaluación de Proyectos | H1: RESUMEN DE LOGRO EVALUACION POR DIMENSIÓN
A3: La escala para la asignación de puntajes en cada descriptor de los criterios a evaluar irá de 1 a 5 con las siguientes consideraciones: | H3: Número | I3: DIMENSION A EVALUAR | J3: Ponderación | K3: Puntaje | L3: (%puntaje)*20
H4: 1 | I4: Ejes estratégicos | J4: 0.2 | K4: =E29 -> 5 | L4: =(K4*J4) -> 1
B5: ESCALA DE PUNTAJES DE EVALUACION | H5: 2 | I5: Análisis de Mercado | J5: 0.1 | K5: =E44 -> 5 | L5: =(K5*J5) -> 0.5
B6: DEFINICIÓN | C6: CATEGORÍA | D6: PUNTAJE | H6: 3 | I6: Análisis de Recursos | J6: 0.1 | K6: =E59 -> 5 | L6: =(K6*J6) -> 0.5
B7: El proyecto no cumple las exigencias del programa. | C7: Deficiente | D7: 1 | H7: 4 | I7: Actividades del proyecto | J7: 0.1 | K7: =E76 -> 5 | L7: =(K7*J7) -> 0.5
B8: El proyecto presenta debilidades significativas respecto de las exigencias del programa. | C8: Insuficiente | D8: 2 | H8: 5 | I8: Conceptos Económicos | J8: 0.2 | K8: =E94 -> 5 | L8: =(K8*J8) -> 1
B9: El proyecto se ajusta mínimamente a las exigencias del programa y no satisface lo requerido. | C9: Regular | D9: 3 | H9: 6 | I9: Rentabilidad Económica | J9: 0.3 | K9: =E107 -> 5 | L9: =(K9*J9) -> 1.5
B10: El proyecto satisface y a veces supera las exigencias del programa. | C10: Bueno | D10: 4 | I10: TOTAL DIMENSION III | J10: =SUM(J4:J9) -> 1 | L10: =SUM(L4:L9) -> 5
B11: El proyecto siempre satisface y en la mayoría de sus propuestas supera las exigencias del programa. | C11: Excelente | D11: 5
H12: OBSERVACIONES GENERALES:
A13: Las observaciones derivadas de esta Pauta en sus cuadros de fortalezas y debilidades, así como en Observaciones Generales serán consideradas como parte del seguimiento de la supervisión técnica que se realizará una vez adjudicado el proyecto y puesto en marcha.
A15: I. DATOS GENERALES
A16: PERIODO DE EVALUACIÓN | B16: Marzo 2025 - Junio 2025
A17: NOMBRE DEL PROYECTO | B17: Pagina Web Hostal-Soft
A18: EJE ESTRATÉGICO AL CUAL SE DIRIGE | B18: Gestión web de hostales de clientes
A19: PUNTAJE FINAL | B19: =L10 -> 5
A23: 1.- | B23: Criterio : Relación del proyecto con los ejes estratégicos de la organización | C23: Ponderador % (A) | D23: Puntaje (B) | E23: (% puntaje) (C)
B24: DESCRIPTORES
A25: 1 | B25: Analiza de manera objetiva los ejes estratégicos correspondientes a la Municipalidad. | C25: 0.2 | D25: 5 | E25: =(D25*C25) -> 1
A26: 2 | B26: Relaciona el proyecto con un eje estratégico de la organización. | C26: 0.3 | D26: 5 | E26: =(D26*C26) -> 1.5
A27: 3 | B27: Define el propósito del proyecto con la finalidad de establecer que problema específico resolverá. | C27: 0.2 | D27: 5 | E27: =(D27*C27) -> 1
A28: 4 | B28: Declara con claridad el proyecto con el fin de entender el propósito del mismo. | C28: 0.3 | D28: 5 | E28: =(D28*C28) -> 1.5
B29: PUNTAJE TOTAL | C29: =SUM(C25:C28) -> 1 | E29: =SUM(E25:E28) -> 5
B31: Observaciones: fundamente brevemente la calificación asignada
B32: Fortalezas | C32: Debilidades
B33: Recursividad de codigo realizado por desarrollo de pagina | C33: 3 mesesde desarrollo
A37: 2.- | B37: Criterio : Analiza el mercado objetivo del proyecto | C37: Ponderador % (A) | D37: Puntaje (B) | E37: (% puntaje) (C)
B38: DESCRIPTORES
A39: 1 | B39: Realiza un instrumento para la realización del Estudio de Mercado para conocer la aceptación del proyecto en la comunidad | C39: 0.25 | D39: 5 | E39: =(D39*C39) -> 1.25
A40: 2 | B40: Identifica aspectos relevantes para la realización del proyecto en base al Estudio de Mercado. | C40: 0.25 | D40: 5 | E40: =(D40*C40) -> 1.25
A41: 3 | B41: Identifica el tamaño de la muestra según los parámetros expuestos por el docente. | C41: 0.2 | D41: 5 | E41: =(D41*C41) -> 1
A42: 4 | B42: Analiza de manera genérica la competencia, con el fin de obtener referencias en el precio del producto. | C42: 0.1 | D42: 5 | E42: =(D42*C42) -> 0.5
A43: 5 | B43: Determina la comercialización del producto en base a criterios acordes al tipo de producto a ofrecer | C43: 0.2 | D43: 5 | E43: =(D43*C43) -> 1
B44: PUNTAJE TOTAL | C44: =SUM(C39:C43) -> 1 | E44: =SUM(E39:E43) -> 5
B46: Observaciones: fundamente brevemente la calificación asignada
B47: Fortalezas | C47: Debilidades
A52: 3.- | B52: Criterio : Establece los recursos óptimos para el desarrollo del proyecto | C52: Ponderador % (A) | D52: Puntaje (B) | E52: (% puntaje) (C)
B53: DESCRIPTORES
A54: 1 | B54: Identifica los recursos humanos necesarios para el desarrollo del proyecto | C54: 0.2 | D54: 5 | E54: =(D54*C54) -> 1
...

Sheet PAUTA 2
A1: Pauta de Evaluación de Proyectos | H1: RESUMEN DE LOGRO EVALUACION POR DIMENSIÓN
A3: La escala para la asignación de puntajes en cada descriptor de los criterios a evaluar irá de 1 a 5 con las siguientes consideraciones: | H3: Número | I3: DIMENSION A EVALUAR | J3: Ponderación | K3: Puntaje | L3: (%puntaje)*20
H4: 1 | I4: Ejes estratégicos | J4: 0.2 | K4: =E29 -> 0 | L4: =(K4*J4) -> 0
B5: ESCALA DE PUNTAJES DE EVALUACION | H5: 2 | I5: Análisis de Mercado | J5: 0.1 | K5: =E44 -> 0 | L5: =(K5*J5) -> 0
B6: DEFINICIÓN | C6: CATEGORÍA | D6: PUNTAJE | H6: 3 | I6: Análisis de Recursos | J6: 0.1 | K6: =E59 -> 0 | L6: =(K6*J6) -> 0
B7: El proyecto no cumple las exigencias del programa. | C7: Deficiente | D7: 1 | H7: 4 | I7: Actividades del proyecto | J7: 0.1 | K7: =E76 -> 0 | L7: =(K7*J7) -> 0
B8: El proyecto presenta debilidades significativas respecto de las exigencias del programa. | C8: Insuficiente | D8: 2 | H8: 5 | I8: Conceptos Económicos | J8: 0.2 | K8: =E94 -> 0 | L8: =(K8*J8) -> 0
B9: El proyecto se ajusta mínimamente a las exigencias del programa y no satisface lo requerido. | C9: Regular | D9: 3 | H9: 6 | I9: Rentabilidad Económica | J9: 0.3 | K9: =E107 -> 0 | L9: =(K9*J9) -> 0
B10: El proyecto satisface y a veces supera las exigencias del programa. | C10: Bueno | D10: 4 | I10: TOTAL DIMENSION III | J10: =SUM(J4:J9) -> 1 | L10: =SUM(L7:L9) -> 0
B11: El proyecto siempre satisface y en la mayoría de sus propuestas supera las exigencias del programa. | C11: Excelente | D11: 5
H12: OBSERVACIONES GENERALES:
A13: Las observaciones derivadas de esta Pauta en sus cuadros de fortalezas y debilidades, así como en Observaciones Generales serán consideradas como parte del seguimiento de la supervisión técnica que se realizará una vez adjudicado el proyecto y puesto en marcha.
A15: I. DATOS GENERALES
A16: PERIODO DE EVALUACIÓN
A17: NOMBRE DEL PROYECTO
A18: EJE ESTRATÉGICO AL CUAL SE DIRIGE
A19: PUNTAJE FINAL | B19: =L10 -> 0
A23: 1.- | B23: Criterio : Relación del proyecto con los ejes estratégicos de la organización | C23: Ponderador % (A) | D23: Puntaje (B) | E23: (% puntaje) (C)
B24: DESCRIPTORES
A25: 1 | B25: Analiza de manera objetiva los ejes estratégicos correspondientes a la Municipalidad. | C25: 0.2 | E25: =(D25*C25) -> 0
A26: 2 | B26: Relaciona el proyecto con un eje estratégico de la organización. | C26: 0.3 | E26: =(D26*C26) -> 0
A27: 3 | B27: Define el propósito del proyecto con la finalidad de establecer que problema específico resolverá. | C27: 0.2 | E27: =(D27*C27) -> 0
A28: 4 | B28: Declara con claridad el proyecto con el fin de entender el propósito del mismo. | C28: 0.3 | E28: =(D28*C28) -> 0
B29: PUNTAJE TOTAL | C29: =SUM(C25:C28) -> 1 | E29: =SUM(E25:E28) -> 0
B31: Observaciones: fundamente brevemente la calificación asignada
B32: Fortalezas | C32: Debilidades
A37: 2.- | B37: Criterio : Analiza el mercado objetivo del proyecto | C37: Ponderador % (A) | D37: Puntaje (B) | E37: (% puntaje) (C)
B38: DESCRIPTORES
A39: 1 | B39: Realiza un instrumento para la realización del Estudio de Mercado para conocer la aceptación del proyecto en la comunidad | C39: 0.25 | E39: =(D39*C39) -> 0
A40: 2 | B40: Identifica aspectos relevantes para la realización del proyecto en base al Estudio de Mercado. | C40: 0.25 | E40: =(D40*C40) -> 0
A41: 3 | B41: Identifica el tamaño de la muestra según los parámetros expuestos por el docente. | C41: 0.2 | E41: =(D41*C41) -> 0
A42: 4 | B42: Analiza de manera genérica la competencia, con el fin de obtener referencias en el precio del producto. | C42: 0.1 | E42: =(D42*C42) -> 0
A43: 5 | B43: Determina la comercialización del producto en base a criterios acordes al tipo de producto a ofrecer | C43: 0.2 | E43: =(D43*C43) -> 0
B44: PUNTAJE TOTAL | C44: =SUM(C39:C43) -> 1 | E44: =SUM(E39:E43) -> 0
B46: Observaciones: fundamente brevemente la calificación asignada
B47: Fortalezas | C47: Debilidades
A52: 3.- | B52: Criterio : Establece los recursos óptimos para el desarrollo del proyecto | C52: Ponderador % (A) | D52: Puntaje (B) | E52: (% puntaje) (C)
B53: DESCRIPTORES
A54: 1 | B54: Identifica los recursos humanos necesarios para el desarrollo del proyecto | C54: 0.2 | E54: =(D54*C54) -> 0
A55: 2 | B55: Identifica los recursos materiales necesarios para el desarrollo del proyecto | C55: 0.2 | E55: =(D55*C55) -> 0
...

Sheet PAUTA 3
A1: Pauta de Evaluación de Proyectos | H1: RESUMEN DE LOGRO EVALUACION POR DIMENSIÓN
A3: La escala para la asignación de puntajes en cada descriptor de los criterios a evaluar irá de 1 a 5 con las siguientes consideraciones: | H3: Número | I3: DIMENSION A EVALUAR | J3: Ponderación | K3: Puntaje | L3: (%puntaje)*20
H4: 1 | I4: Ejes estratégicos | J4: 0.2 | K4: =E29 -> 5 | L4: =(K4*J4) -> 1
B5: ESCALA DE PUNTAJES DE EVALUACION | H5: 2 | I5: Análisis de Mercado | J5: 0.1 | K5: =E44 -> 3.5 | L5: =(K5*J5) -> 0.35
B6: DEFINICIÓN | C6: CATEGORÍA | D6: PUNTAJE | H6: 3 | I6: Análisis de Recursos | J6: 0.1 | K6: =E60 -> 5 | L6: =(K6*J6) -> 0.5
B7: El proyecto no cumple las exigencias del programa. | C7: Deficiente | D7: 1 | H7: 4 | I7: Actividades del proyecto | J7: 0.1 | K7: =E77 -> 2.3 | L7: =(K7*J7) -> 0.23
B8: El proyecto presenta debilidades significativas respecto de las exigencias del programa. | C8: Insuficiente | D8: 2 | H8: 5 | I8: Conceptos Económicos | J8: 0.2 | K8: =E95 -> 5 | L8: =(K8*J8) -> 1
B9: El proyecto se ajusta mínimamente a las exigencias del programa y no satisface lo requerido. | C9: Regular | D9: 3 | H9: 6 | I9: Rentabilidad Económica | J9: 0.3 | K9: =E108 -> 5 | L9: =(K9*J9) -> 1.5
B10: El proyecto satisface y a veces supera las exigencias del programa. | C10: Bueno | D10: 4 | I10: TOTAL DIMENSION III | J10: =SUM(J4:J9) -> 1 | L10: =SUM(L4:L9) -> 4.58
B11: El proyecto siempre satisface y en la mayoría de sus propuestas supera las exigencias del programa. | C11: Excelente | D11: 5
H12: OBSERVACIONES GENERALES:
A13: Las observaciones derivadas de esta Pauta en sus cuadros de fortalezas y debilidades, así como en Observaciones Generales serán consideradas como parte del seguimiento de la supervisión técnica que se realizará una vez adjudicado el proyecto y puesto en marcha.
A15: I. DATOS GENERALES
A16: PERIODO DE EVALUACIÓN | B16: Junio 2025 - Julio 2025
A17: NOMBRE DEL PROYECTO | B17: Web Movil Hostal-Soft
A18: EJE ESTRATÉGICO AL CUAL SE DIRIGE | B18: Tecnologia portable para clientes
A19: PUNTAJE FINAL | B19: =L10 -> 4.58
A23: 1.- | B23: Criterio : Relación del proyecto con los ejes estratégicos de la organización | C23: Ponderador % (A) | D23: Puntaje (B) | E23: (% puntaje) (C)
B24: DESCRIPTORES
A25: 1 | B25: Analiza de manera objetiva los ejes estratégicos correspondientes a la Municipalidad. | C25: 0.2 | D25: 5 | E25: =(D25*C25) -> 1
A26: 2 | B26: Relaciona el proyecto con un eje estratégico de la organización. | C26: 0.3 | D26: 5 | E26: =(D26*C26) -> 1.5
A27: 3 | B27: Define el propósito del proyecto con la finalidad de establecer que problema específico resolverá. | C27: 0.2 | D27: 5 | E27: =(D27*C27) -> 1
A28: 4 | B28: Declara con claridad el proyecto con el fin de entender el propósito del mismo. | C28: 0.3 | D28: 5 | E28: =(D28*C28) -> 1.5
B29: PUNTAJE TOTAL | C29: =SUM(C25:C28) -> 1 | E29: =SUM(E25:E28) -> 5
B31: Observaciones: fundamente brevemente la calificación asignada
B32: Fortalezas | C32: Debilidades
B33: - Mayor portabilidad al proyecto - Más amigable con el usuario - Solo requiere reutilizar algunos recursos ya existentes para su desarollo
A37: 2.- | B37: Criterio : Analiza el mercado objetivo del proyecto | C37: Ponderador % (A) | D37: Puntaje (B) | E37: (% puntaje) (C)
B38: DESCRIPTORES
A39: 1 | B39: Realiza un instrumento para la realización del Estudio de Mercado para conocer la aceptación del proyecto en la comunidad | C39: 0.25 | D39: 5 | E39: =(D39*C39) -> 1.25
A40: 2 | B40: Identifica aspectos relevantes para la realización del proyecto en base al Estudio de Mercado. | C40: 0.25 | D40: 5 | E40: =(D40*C40) -> 1.25
A41: 3 | B41: Identifica el tamaño de la muestra según los parámetros expuestos por el docente. | C41: 0.2 | D41: 2 | E41: =(D41*C41) -> 0.4
A42: 4 | B42: Analiza de manera genérica la competencia, con el fin de obtener referencias en el precio del producto. | C42: 0.1 | D42: 4 | E42: =(D42*C42) -> 0.4
A43: 5 | B43: Determina la comercialización del producto en base a criterios acordes al tipo de producto a ofrecer | C43: 0.2 | D43: 1 | E43: =(D43*C43) -> 0.2
B44: PUNTAJE TOTAL | C44: =SUM(C39:C43) -> 1 | E44: =SUM(E39:E43) -> 3.5
B46: Observaciones: fundamente brevemente la calificación asignada
B47: Fortalezas | C47: Debilidades
B48: - La mayoria de los usuarios tiene un smartphone y saben usarlos parar realizar procesos y completar formularios - Muchas empresas ya estan implementando este tipo de soluciones | C48: - La tercera edad requiere mayor capacitacion
A53: 3.- | B53: Criterio : Establece los recursos óptimos para el desarrollo del proyecto | C53: Ponderador % (A) | D53: Puntaje (B) | E53: (% puntaje) (C)
B54: DESCRIPTORES
...

Sheet PAUTA 4
A1: Pauta de Evaluación de Proyectos | H1: RESUMEN DE LOGRO EVALUACION POR DIMENSIÓN
A3: La escala para la asignación de puntajes en cada descriptor de los criterios a evaluar irá de 1 a 5 con las siguientes consideraciones: | H3: Número | I3: DIMENSION A EVALUAR | J3: Ponderación | K3: Puntaje | L3: (%puntaje)*20
H4: 1 | I4: Ejes estratégicos | J4: 0.2 | K4: =E29 -> 0 | L4: =(K4*J4) -> 0
B5: ESCALA DE PUNTAJES DE EVALUACION | H5: 2 | I5: Análisis de Mercado | J5: 0.1 | K5: =E44 -> 0 | L5: =(K5*J5) -> 0
B6: DEFINICIÓN | C6: CATEGORÍA | D6: PUNTAJE | H6: 3 | I6: Análisis de Recursos | J6: 0.1 | K6: =E59 -> 0 | L6: =(K6*J6) -> 0
B7: El proyecto no cumple las exigencias del programa. | C7: Deficiente | D7: 1 | H7: 4 | I7: Actividades del proyecto | J7: 0.1 | K7: =E76 -> 0 | L7: =(K7*J7) -> 0
B8: El proyecto presenta debilidades significativas respecto de las exigencias del programa. | C8: Insuficiente | D8: 2 | H8: 5 | I8: Conceptos Económicos | J8: 0.2 | K8: =E94 -> 0 | L8: =(K8*J8) -> 0
B9: El proyecto se ajusta mínimamente a las exigencias del programa y no satisface lo requerido. | C9: Regular | D9: 3 | H9: 6 | I9: Rentabilidad Económica | J9: 0.3 | K9: =E107 -> 0 | L9: =(K9*J9) -> 0
B10: El proyecto satisface y a veces supera las exigencias del programa. | C10: Bueno | D10: 4 | I10: TOTAL DIMENSION III | J10: =SUM(J4:J9) -> 1 | L10: =SUM(L7:L9) -> 0
B11: El proyecto siempre satisface y en la mayoría de sus propuestas supera las exigencias del programa. | C11: Excelente | D11: 5
H12: OBSERVACIONES GENERALES:
A13: Las observaciones derivadas de esta Pauta en sus cuadros de fortalezas y debilidades, así como en Observaciones Generales serán consideradas como parte del seguimiento de la supervisión técnica que se realizará una vez adjudicado el proyecto y puesto en marcha.
A15: I. DATOS GENERALES
A16: PERIODO DE EVALUACIÓN
A17: NOMBRE DEL PROYECTO
A18: EJE ESTRATÉGICO AL CUAL SE DIRIGE
A19: PUNTAJE FINAL | B19: =L10 -> 0
A23: 1.- | B23: Criterio : Relación del proyecto con los ejes estratégicos de la organización | C23: Ponderador % (A) | D23: Puntaje (B) | E23: (% puntaje) (C)
B24: DESCRIPTORES
A25: 1 | B25: Analiza de manera objetiva los ejes estratégicos correspondientes a la Municipalidad. | C25: 0.2 | E25: =(D25*C25) -> 0
A26: 2 | B26: Relaciona el proyecto con un eje estratégico de la organización. | C26: 0.3 | E26: =(D26*C26) -> 0
A27: 3 | B27: Define el propósito del proyecto con la finalidad de establecer que problema específico resolverá. | C27: 0.2 | E27: =(D27*C27) -> 0
A28: 4 | B28: Declara con claridad el proyecto con el fin de entender el propósito del mismo. | C28: 0.3 | E28: =(D28*C28) -> 0
B29: PUNTAJE TOTAL | C29: =SUM(C25:C28) -> 1 | E29: =SUM(E25:E28) -> 0
B31: Observaciones: fundamente brevemente la calificación asignada
B32: Fortalezas | C32: Debilidades
A37: 2.- | B37: Criterio : Analiza el mercado objetivo del proyecto | C37: Ponderador % (A) | D37: Puntaje (B) | E37: (% puntaje) (C)
B38: DESCRIPTORES
A39: 1 | B39: Realiza un instrumento para la realización del Estudio de Mercado para conocer la aceptación del proyecto en la comunidad | C39: 0.25 | E39: =(D39*C39) -> 0
A40: 2 | B40: Identifica aspectos relevantes para la realización del proyecto en base al Estudio de Mercado. | C40: 0.25 | E40: =(D40*C40) -> 0
A41: 3 | B41: Identifica el tamaño de la muestra según los parámetros expuestos por el docente. | C41: 0.2 | E41: =(D41*C41) -> 0
A42: 4 | B42: Analiza de manera genérica la competencia, con el fin de obtener referencias en el precio del producto. | C42: 0.1 | E42: =(D42*C42) -> 0
A43: 5 | B43: Determina la comercialización del producto en base a criterios acordes al tipo de producto a ofrecer | C43: 0.2 | E43: =(D43*C43) -> 0
B44: PUNTAJE TOTAL | C44: =SUM(C39:C43) -> 1 | E44: =SUM(E39:E43) -> 0
B46: Observaciones: fundamente brevemente la calificación asignada
B47: Fortalezas | C47: Debilidades
A52: 3.- | B52: Criterio : Establece los recursos óptimos para el desarrollo del proyecto | C52: Ponderador % (A) | D52: Puntaje (B) | E52: (% puntaje) (C)
B53: DESCRIPTORES
A54: 1 | B54: Identifica los recursos humanos necesarios para el desarrollo del proyecto | C54: 0.2 | E54: =(D54*C54) -> 0
A55: 2 | B55: Identifica los recursos materiales necesarios para el desarrollo del proyecto | C55: 0.2 | E55: =(D55*C55) -> 0
...

Sheet PAUTA 5
A1: Pauta de Evaluación de Proyectos | H1: RESUMEN DE LOGRO EVALUACION POR DIMENSIÓN
A3: La escala para la asignación de puntajes en cada descriptor de los criterios a evaluar irá de 1 a 5 con las siguientes consideraciones: | H3: Número | I3: DIMENSION A EVALUAR | J3: Ponderación | K3: Puntaje | L3: (%puntaje)*20
H4: 1 | I4: Ejes estratégicos | J4: 0.2 | K4: =E29 -> 0 | L4: =(K4*J4) -> 0
B5: ESCALA DE PUNTAJES DE EVALUACION | H5: 2 | I5: Análisis de Mercado | J5: 0.1 | K5: =E44 -> 0 | L5: =(K5*J5) -> 0
B6: DEFINICIÓN | C6: CATEGORÍA | D6: PUNTAJE | H6: 3 | I6: Análisis de Recursos | J6: 0.1 | K6: =E59 -> 0 | L6: =(K6*J6) -> 0
B7: El proyecto no cumple las exigencias del programa. | C7: Deficiente | D7: 1 | H7: 4 | I7: Actividades del proyecto | J7: 0.1 | K7: =E76 -> 0 | L7: =(K7*J7) -> 0
B8: El proyecto presenta debilidades significativas respecto de las exigencias del programa. | C8: Insuficiente | D8: 2 | H8: 5 | I8: Conceptos Económicos | J8: 0.2 | K8: =E94 -> 0 | L8: =(K8*J8) -> 0
B9: El proyecto se ajusta mínimamente a las exigencias del programa y no satisface lo requerido. | C9: Regular | D9: 3 | H9: 6 | I9: Rentabilidad Económica | J9: 0.3 | K9: =E107 -> 0 | L9: =(K9*J9) -> 0
B10: El proyecto satisface y a veces supera las exigencias del programa. | C10: Bueno | D10: 4 | I10: TOTAL DIMENSION III | J10: =SUM(J4:J9) -> 1 | L10: =SUM(L7:L9) -> 0
B11: El proyecto siempre satisface y en la mayoría de sus propuestas supera las exigencias del programa. | C11: Excelente | D11: 5
H12: OBSERVACIONES GENERALES:
A13: Las observaciones derivadas de esta Pauta en sus cuadros de fortalezas y debilidades, así como en Observaciones Generales serán consideradas como parte del seguimiento de la supervisión técnica que se realizará una vez adjudicado el proyecto y puesto en marcha.
A15: I. DATOS GENERALES
A16: PERIODO DE EVALUACIÓN
A17: NOMBRE DEL PROYECTO
A18: EJE ESTRATÉGICO AL CUAL SE DIRIGE
A19: PUNTAJE FINAL | B19: =L10 -> 0
A23: 1.- | B23: Criterio : Relación del proyecto con los ejes estratégicos de la organización | C23: Ponderador % (A) | D23: Puntaje (B) | E23: (% puntaje) (C)
B24: DESCRIPTORES
A25: 1 | B25: Analiza de manera objetiva los ejes estratégicos correspondientes a la Municipalidad. | C25: 0.2 | E25: =(D25*C25) -> 0
A26: 2 | B26: Relaciona el proyecto con un eje estratégico de la organización. | C26: 0.3 | E26: =(D26*C26) -> 0
A27: 3 | B27: Define el propósito del proyecto con la finalidad de establecer que problema específico resolverá. | C27: 0.2 | E27: =(D27*C27) -> 0
A28: 4 | B28: Declara con claridad el proyecto con el fin de entender el propósito del mismo. | C28: 0.3 | E28: =(D28*C28) -> 0
B29: PUNTAJE TOTAL | C29: =SUM(C25:C28) -> 1 | E29: =SUM(E25:E28) -> 0
B31: Observaciones: fundamente brevemente la calificación asignada
B32: Fortalezas | C32: Debilidades
A37: 2.- | B37: Criterio : Analiza el mercado objetivo del proyecto | C37: Ponderador % (A) | D37: Puntaje (B) | E37: (% puntaje) (C)
B38: DESCRIPTORES
A39: 1 | B39: Realiza un instrumento para la realización del Estudio de Mercado para conocer la aceptación del proyecto en la comunidad | C39: 0.25 | E39: =(D39*C39) -> 0
A40: 2 | B40: Identifica aspectos relevantes para la realización del proyecto en base al Estudio de Mercado. | C40: 0.25 | E40: =(D40*C40) -> 0
A41: 3 | B41: Identifica el tamaño de la muestra según los parámetros expuestos por el docente. | C41: 0.2 | E41: =(D41*C41) -> 0
A42: 4 | B42: Analiza de manera genérica la competencia, con el fin de obtener referencias en el precio del producto. | C42: 0.1 | E42: =(D42*C42) -> 0
A43: 5 | B43: Determina la comercialización del producto en base a criterios acordes al tipo de producto a ofrecer | C43: 0.2 | E43: =(D43*C43) -> 0
B44: PUNTAJE TOTAL | C44: =SUM(C39:C43) -> 1 | E44: =SUM(E39:E43) -> 0
B46: Observaciones: fundamente brevemente la calificación asignada
B47: Fortalezas | C47: Debilidades
A52: 3.- | B52: Criterio : Establece los recursos óptimos para el desarrollo del proyecto | C52: Ponderador % (A) | D52: Puntaje (B) | E52: (% puntaje) (C)
B53: DESCRIPTORES
A54: 1 | B54: Identifica los recursos humanos necesarios para el desarrollo del proyecto | C54: 0.2 | E54: =(D54*C54) -> 0
A55: 2 | B55: Identifica los recursos materiales necesarios para el desarrollo del proyecto | C55: 0.2 | E55: =(D55*C55) -> 0
...

Sheet PAUTA 6
A1: Pauta de Evaluación de Proyectos | H1: RESUMEN DE LOGRO EVALUACION POR DIMENSIÓN
A3: La escala para la asignación de puntajes en cada descriptor de los criterios a evaluar irá de 1 a 5 con las siguientes consideraciones: | H3: Número | I3: DIMENSION A EVALUAR | J3: Ponderación | K3: Puntaje | L3: (%puntaje)*20
H4: 1 | I4: Ejes estratégicos | J4: 0.2 | K4: =E29 -> 0 | L4: =(K4*J4) -> 0
B5: ESCALA DE PUNTAJES DE EVALUACION | H5: 2 | I5: Análisis de Mercado | J5: 0.1 | K5: =E44 -> 0 | L5: =(K5*J5) -> 0
B6: DEFINICIÓN | C6: CATEGORÍA | D6: PUNTAJE | H6: 3 | I6: Análisis de Recursos | J6: 0.1 | K6: =E59 -> 0 | L6: =(K6*J6) -> 0
B7: El proyecto no cumple las exigencias del programa. | C7: Deficiente | D7: 1 | H7: 4 | I7: Actividades del proyecto | J7: 0.1 | K7: =E76 -> 0 | L7: =(K7*J7) -> 0
B8: El proyecto presenta debilidades significativas respecto de las exigencias del programa. | C8: Insuficiente | D8: 2 | H8: 5 | I8: Conceptos Económicos | J8: 0.2 | K8: =E94 -> 0 | L8: =(K8*J8) -> 0
B9: El proyecto se ajusta mínimamente a las exigencias del programa y no satisface lo requerido. | C9: Regular | D9: 3 | H9: 6 | I9: Rentabilidad Económica | J9: 0.3 | K9: =E107 -> 0 | L9: =(K9*J9) -> 0
B10: El proyecto satisface y a veces supera las exigencias del programa. | C10: Bueno | D10: 4 | I10: TOTAL DIMENSION III | J10: =SUM(J4:J9) -> 1 | L10: =SUM(L7:L9) -> 0
B11: El proyecto siempre satisface y en la mayoría de sus propuestas supera las exigencias del programa. | C11: Excelente | D11: 5
H12: OBSERVACIONES GENERALES:
A13: Las observaciones derivadas de esta Pauta en sus cuadros de fortalezas y debilidades, así como en Observaciones Generales serán consideradas como parte del seguimiento de la supervisión técnica que se realizará una vez adjudicado el proyecto y puesto en marcha.
A15: I. DATOS GENERALES
A16: PERIODO DE EVALUACIÓN
A17: NOMBRE DEL PROYECTO
A18: EJE ESTRATÉGICO AL CUAL SE DIRIGE
A19: PUNTAJE FINAL | B19: =L10 -> 0
A23: 1.- | B23: Criterio : Relación del proyecto con los ejes estratégicos de la organización | C23: Ponderador % (A) | D23: Puntaje (B) | E23: (% puntaje) (C)
B24: DESCRIPTORES
A25: 1 | B25: Analiza de manera objetiva los ejes estratégicos correspondientes a la Municipalidad. | C25: 0.2 | E25: =(D25*C25) -> 0
A26: 2 | B26: Relaciona el proyecto con un eje estratégico de la organización. | C26: 0.3 | E26: =(D26*C26) -> 0
A27: 3 | B27: Define el propósito del proyecto con la finalidad de establecer que problema específico resolverá. | C27: 0.2 | E27: =(D27*C27) -> 0
A28: 4 | B28: Declara con claridad el proyecto con el fin de entender el propósito del mismo. | C28: 0.3 | E28: =(D28*C28) -> 0
B29: PUNTAJE TOTAL | C29: =SUM(C25:C28) -> 1 | E29: =SUM(E25:E28) -> 0
B31: Observaciones: fundamente brevemente la calificación asignada
B32: Fortalezas | C32: Debilidades
A37: 2.- | B37: Criterio : Analiza el mercado objetivo del proyecto | C37: Ponderador % (A) | D37: Puntaje (B) | E37: (% puntaje) (C)
B38: DESCRIPTORES
A39: 1 | B39: Realiza un instrumento para la realización del Estudio de Mercado para conocer la aceptación del proyecto en la comunidad | C39: 0.25 | E39: =(D39*C39) -> 0
A40: 2 | B40: Identifica aspectos relevantes para la realización del proyecto en base al Estudio de Mercado. | C40: 0.25 | E40: =(D40*C40) -> 0
A41: 3 | B41: Identifica el tamaño de la muestra según los parámetros expuestos por el docente. | C41: 0.2 | E41: =(D41*C41) -> 0
A42: 4 | B42: Analiza de manera genérica la competencia, con el fin de obtener referencias en el precio del producto. | C42: 0.1 | E42: =(D42*C42) -> 0
A43: 5 | B43: Determina la comercialización del producto en base a criterios acordes al tipo de producto a ofrecer | C43: 0.2 | E43: =(D43*C43) -> 0
B44: PUNTAJE TOTAL | C44: =SUM(C39:C43) -> 1 | E44: =SUM(E39:E43) -> 0
B46: Observaciones: fundamente brevemente la calificación asignada
B47: Fortalezas | C47: Debilidades
A52: 3.- | B52: Criterio : Establece los recursos óptimos para el desarrollo del proyecto | C52: Ponderador % (A) | D52: Puntaje (B) | E52: (% puntaje) (C)
B53: DESCRIPTORES
A54: 1 | B54: Identifica los recursos humanos necesarios para el desarrollo del proyecto | C54: 0.2 | E54: =(D54*C54) -> 0
A55: 2 | B55: Identifica los recursos materiales necesarios para el desarrollo del proyecto | C55: 0.2 | E55: =(D55*C55) -> 0
...

Sheet PUNTAJES FINALES
C3: Número | D3: NOMBRE DEL PROYECTO | E3: PUNTAJ FINAL
C4: 1 | D4: =+'PAUTA 1'!B17 -> Pagina Web Hostal-Soft | E4: ='PAUTA 1'!B19 -> 5
C5: 2 | D5: =+'PAUTA 2'!B17 | E5: ='PAUTA 2'!B19 -> 0
C6: 3 | D6: =+'PAUTA 3'!B17 -> Web Movil Hostal-Soft | E6: ='PAUTA 3'!B19 -> 4.58
C7: 4 | D7: =+'PAUTA 4'!B17 | E7: ='PAUTA 4'!B19:E19
C8: 5 | D8: =+'PAUTA 5'!B17 | E8: ='PAUTA 5'!B19:E19
C9: 6 | D9: =+'PAUTA 6'!B17 | E9: ='PAUTA 6'!B19:E19
C11: OBSERVACIONES GENERALES:
